Workbook
Name a: #REF!
Name ABAP: #REF!
Name ABAP: #REF!
Name ABAP: #REF!
Name Administrator: 'Role Selection'!$O$12:$O$38
Name Administrator: #REF!
Name Administrator: #REF!
Name AdministratorBIDW: 'Role Selection'!$DZ$12:$DZ$38
Name AdministratorBIDW: #REF!
Name AdministratorBIDW: #REF!
Name AdministratorMiddleware: 'Role Selection'!$AO$12:$AO$38
Name AdministratorMiddleware: #REF!
Name AdministratorMiddleware: #REF!
Name AdministratorNetwork: 'Role Selection'!$AQ$12:$AQ$38
Name AdministratorNetwork: #REF!
Name AdministratorNetwork: #REF!
Name AdministratorSecurity: 'Role Selection'!$AS$12:$AS$38
Name AdministratorSecurity: #REF!
Name AdministratorSecurity: #REF!
Name AdministratorSharepoint: 'Role Selection'!$V$12:$V$38
Name AdministratorSharepoint: #REF!
Name AdministratorSharepoint: #REF!
Name AdministratorStorage: 'Role Selection'!$AU$12:$AU$38
Name AdministratorStorage: #REF!
Name AdministratorStorage: #REF!
Name AdministratorSystems: 'Role Selection'!$BA$12:$BA$38
Name AdministratorSystems: #REF!
Name AdministratorSystems: #REF!
Name AdministratorSystemsMSSQLOracle: 'Role Selection'!$AY$12:$AY$38
Name AdministratorSystemsMSSQLOracle: #REF!
Name AdministratorSystemsMSSQLOracle: #REF!
Name AdministratorSystemsSolaris: 'Role Selection'!$AW$12:$AW$38
Name AdministratorSystemsSolaris: #REF!
Name AdministratorSystemsSolaris: #REF!
Name AdministratorSystemsSybase: 'Role Selection'!$AZ$12:$AZ$38
Name AdministratorSystemsSybase: #REF!
Name AdministratorSystemsSybase: #REF!
Name AdministratorSystemsVMWareSCCMCitrix: 'Role Selection'!$AX$12:$AX$38
Name AdministratorSystemsVMWareSCCMCitrix: #REF!
Name AdministratorSystemsVMWareSCCMCitrix: #REF!
Name ADS: 'Role Selection'!$BR$12:$BR$17
Name ADS: #REF!
Name ADS: #REF!
Name Amdocs: 'Role Selection'!$CU$12:$CU$38
Name Amdocs: #REF!
Name Amdocs: #REF!
Name AnalystBusinessRules: 'Role Selection'!$EO$12:$EO$38
Name AnalystBusinessRules: #REF!
Name AnalystBusinessRules: #REF!
Name ApplicationArchitect: 'Role Selection'!$DV$30:$DV$33
Name ApplicationArchitect: #REF!
Name ApplicationArchitect: #REF!
Name Architect: 'Role Selection'!$P$12:$P$36
Name Architect: #REF!
Name Architect: #REF!
Name ArchitectAIMS: 'Role Selection'!$AD$12:$AD$36
Name ArchitectAIMS: #REF!
Name ArchitectAIMS: #REF!
Name ArchitectASG: 'Role Selection'!$DX$12:$DX$38
Name ArchitectASG: #REF!

Sheet CheckList
A1: Checklist for Costing & Pricing of Other Countries Projects | P1: Select | Q1: Select | R1: Select
P2: Client facility | Q2: Pune -GDC | R2: YES
A3: =IF(P18=46,"MESSAGE - Okay to upload this file in CRM.","ERROR MESSAGE - It is mandatory to fill in all the cells coloured in yellow. Please fill in NA if not required") -> ERROR MESSAGE - It is mandatory to fill in all the cells coloured in yellow. Please fill in NA if not required | P3: Syntel facility | Q3: Pune Other | R3: NO
P4: Not Applicable | Q4: Mumbai
A5: Client Name: | M5: =IF(G5="",0,1) -> 0 | Q5: Chennai | R5: Select
A6: Names of Solution & Sales SPOC: | M6: =IF(G6="",0,1) -> 0 | Q6: Delhi | R6: Fixed Price - Development
A7: Contact numbers: | M7: =IF(G7="",0,1) -> 0 | Q7: Hyderabad | R7: Fixed Price - Maintenance
A8: Opportunity ID in CRM: | M8: =IF(G8="",0,1) -> 0 | Q8: Other | R8: Time & Material
A9: Staffing Plan ID in CRM: | M9: =IF(G9="",0,1) -> 0 | U9: Added
Q10: Not Applicable | R10: Managed T & M
A11: 1. What is the Technology involved ?
A12: 1 (a). Generic Technology Skill % (as per staffing plan) | G12: 1
A13: 1 (b). SOG / Niche Technology Skill % (as per staffing plan) | G13: =1-G12 -> 0
A14: 1 (b) i. Provide names & employee ids of SOG / Niche resources if identified (as per staffing plan) | G14: NO
A15: Name with visa status | G15: NA
A16: Employee id | G16: NA
A18: 1. Onsite location: | M18: =IF(G18="",0,1) -> 0 | P18: =SUM(M5:M112) -> 29
A19: Onsite Facility: | G19: Select | M19: =IF(G19="Select",0,1) -> 0
A20: Offshore location: | G20: Select | M20: =IF(G20="Select",0,1) -> 0
A22: 2. Is the staffing for a New deal / Renewal / Change Request (Scope Increase / Extension) ? | G22: Select | M22: =IF(G22="Select",0,1) -> 0
A24: 3. If the answer to above question is other than 'New Deal', pls provide the Original Deal id? | G24: 0 | M24: =IF(G22="New Deal",1,IF(G24="",0,1)) -> 1
A26: 4. If the staffing is for Renewal / Change Request (Scope Increase / Extension), please provide Old PID | G26: 0
A28: 5. If there are employees onsite (Local resources), how many of them will be relocated ? | G28: 0 | M28: =IF(G28="",0,1) -> 1
A30: 6. Onsite travels : No. of Long Term deputed travels | G30: 0 | M30: =IF(G30="",0,1) -> 1
A31: No. of Short Term deputed travels | G31: 0 | M31: =IF(G31="",0,1) -> 1
M32: =IF(G32="",0,1) -> 0
A34: 7. Will there be any additional travel /rotation and if so the number of trips and duration of each trip ? | G34: 0 | M34: =IF(G34="",0,1) -> 1
A36: 8. Is there any additional HW/SW/Connectivity/other costs specifically for this project ? If yes, pls fill in the details in Hardware Software Cost tab. | G36: =+'Hardware Software Cost'!F42 -> 0 | M36: =IF(G36="",0,1) -> 1
A38: 9. Will there be any specialized training required for the project and if so what is the cost of training ? | G38: 0 | M38: =IF(G38="",0,1) -> 1
A40: 10. No. of Offshore resources working in second shift & their duration | G40: 0 | M40: =IF(G40="",0,1) -> 1
A41: No. of offshore resources working in night shift & their duration | G41: 0 | M41: =IF(G41="",0,1) -> 1
A43: 11 (a). Deal Type? | G43: Fixed Price - Development | M43: =IF(G43="Select",0,1) -> 1
A44: 11 (b). Is there any target price that we are looking to quote ? | G44: NO | M44: =IF(G44="Select",0,1) -> 1
A45: 11 (c). Target price? | G45: 0 | M45: =IF(G44="NO",1,IF(G45>0,1,0)) -> 1
A47: 12. FP Scope? | G47: Select | M47: =IF(G47="Select",0,1) -> 0
A49: 13. Who controls the Staffing, On/Off Mix, Role Mix? | G49: Select | M49: =IF(G49="Select",0,1) -> 0
A50: (The expectation is that staffing, On/Off Mix, Role Mix for FP should be controlled by Syntel)
A52: 14. Details of contractor’s resources involved (Onsite), if any. | G52: NO | M52: =IF(G52="Select",0,1) -> 1
A53: Name | G53: 0 | M53: =IF(G52="NO",1,IF(G53="",0,1)) -> 1
A54: Employee id | G54: 0 | M54: =IF(G52="NO",1,IF(G54="",0,1)) -> 1
...

Sheet Role Selection
A1: Instructions:
A2: 1. Please go by the following path for Role Selection: Practice --> Sub-Practice --> Role --> Proficiency Level. If you wish to make any changes to the selected role, please follow the same path mentioned above. | HR2: =+CheckList!G78 -> 8 | HS2: =+CheckList!G79 -> 8.5
A3: 2. When selecting roles, please ensure that usage of roles with campus hires (B2 AP1) at offshore is at least 8% of the total offshore utlization | HR3: =+HR2*21.67 -> 173.36 | HS3: =+HS2*21.67 -> 184.195 | HX3: =+CheckList!G82 -> 168 | HY3: =+CheckList!G83 -> 178.5
A4: 3. In absence of customer ratecard, please use GRC recommended rates in columns I and J. | HP4: Total Efforts | HR4: Hrs as per Finance | HT4: Total TCV as per Finance | HX4: Total TCV as per MSA
A5: Sr. No. | B5: Practice | C5: Sub - Practice | D5: Role | E5: Proficiency Level | F5: Combination of Role | G5: Role Code | H5: Band & Grade | I5: Onsite Rates | J5: Offshore Rates | HO5: Client Roles | HP5: Onsite | HQ5: Offshore | HR5: Onsite | HS5: Offshore | HT5: Onsite | HU5: Offshore | HV5: Total | HX5: Onsite | HY5: Offshore | HZ5: Total
A6: 1 | B6: IT | C6: JavaNetColdFusionIT | D6: DeveloperJavaNetColdFusion | E6: Junior | F6: =+B6&"/"&C6&"/"&D6&"/"&E6 -> IT/JavaNetColdFusionIT/DeveloperJavaNetColdFusion/Junior | G6: =VLOOKUP($F6,$Q$101:$T$1500,3,0) -> IT_23 | H6: =+IFERROR(VLOOKUP($G6,$C$505:$O$1001,13,0),0) -> B2 AP1 / B2 AP2 (0.6 to 3 yrs) | HP6: =+'Staffing-Roles'!DS114 -> 0 | HQ6: =+'Staffing-Roles'!DS141 -> 0 | HR6: =+HP6*$HR$3 -> 0 | HS6: =+HQ6*$HS$3 -> 0 | HT6: =+HR6*I6 -> 0 | HU6: =+HS6*J6 -> 0 | HV6: =+HT6+HU6 -> 0 | HX6: =+(HP6*$HX$3)*I6 -> 0 | HY6: =+(HQ6*$HY$3)*J6 -> 0 | HZ6: =+HX6+HY6 -> 0
A7: =+A6+1 -> 2 | F7: =+B7&"/"&C7&"/"&D7&"/"&E7 -> /// | G7: =VLOOKUP($F7,$Q$101:$T$1500,3,0) -> 0 | H7: =+IFERROR(VLOOKUP($G7,$C$505:$O$1001,13,0),0) -> 0 | HP7: =+'Staffing-Roles'!DS115 -> 0 | HQ7: =+'Staffing-Roles'!DS142 -> 0 | HR7: =+HP7*$HR$3 -> 0 | HS7: =+HQ7*$HS$3 -> 0 | HT7: =+HR7*I7 -> 0 | HU7: =+HS7*J7 -> 0 | HV7: =+HT7+HU7 -> 0 | HX7: =+(HP7*$HX$3)*I7 -> 0 | HY7: =+(HQ7*$HY$3)*J7 -> 0 | HZ7: =+HX7+HY7 -> 0
A8: =+A7+1 -> 3 | F8: =+B8&"/"&C8&"/"&D8&"/"&E8 -> /// | G8: =VLOOKUP($F8,$Q$101:$T$1500,3,0) -> 0 | H8: =+IFERROR(VLOOKUP($G8,$C$505:$O$1001,13,0),0) -> 0 | HP8: =+'Staffing-Roles'!DS116 -> 0 | HQ8: =+'Staffing-Roles'!DS143 -> 0 | HR8: =+HP8*$HR$3 -> 0 | HS8: =+HQ8*$HS$3 -> 0 | HT8: =+HR8*I8 -> 0 | HU8: =+HS8*J8 -> 0 | HV8: =+HT8+HU8 -> 0 | HX8: =+(HP8*$HX$3)*I8 -> 0 | HY8: =+(HQ8*$HY$3)*J8 -> 0 | HZ8: =+HX8+HY8 -> 0
A9: =+A8+1 -> 4 | F9: =+B9&"/"&C9&"/"&D9&"/"&E9 -> /// | G9: =VLOOKUP($F9,$Q$101:$T$1500,3,0) -> 0 | H9: =+IFERROR(VLOOKUP($G9,$C$505:$O$1001,13,0),0) -> 0 | K9: Master Data :- | HP9: =+'Staffing-Roles'!DS117 -> 0 | HQ9: =+'Staffing-Roles'!DS144 -> 0 | HR9: =+HP9*$HR$3 -> 0 | HS9: =+HQ9*$HS$3 -> 0 | HT9: =+HR9*I9 -> 0 | HU9: =+HS9*J9 -> 0 | HV9: =+HT9+HU9 -> 0 | HX9: =+(HP9*$HX$3)*I9 -> 0 | HY9: =+(HQ9*$HY$3)*J9 -> 0 | HZ9: =+HX9+HY9 -> 0
A10: =+A9+1 -> 5 | F10: =+B10&"/"&C10&"/"&D10&"/"&E10 -> /// | G10: =VLOOKUP($F10,$Q$101:$T$1500,3,0) -> 0 | H10: =+IFERROR(VLOOKUP($G10,$C$505:$O$1001,13,0),0) -> 0 | HP10: =+'Staffing-Roles'!DS118 -> 0 | HQ10: =+'Staffing-Roles'!DS145 -> 0 | HR10: =+HP10*$HR$3 -> 0 | HS10: =+HQ10*$HS$3 -> 0 | HT10: =+HR10*I10 -> 0 | HU10: =+HS10*J10 -> 0 | HV10: =+HT10+HU10 -> 0 | HX10: =+(HP10*$HX$3)*I10 -> 0 | HY10: =+(HQ10*$HY$3)*J10 -> 0 | HZ10: =+HX10+HY10 -> 0
A11: =+A10+1 -> 6 | F11: =+B11&"/"&C11&"/"&D11&"/"&E11 -> /// | G11: =VLOOKUP($F11,$Q$101:$T$1500,3,0) -> 0 | H11: =+IFERROR(VLOOKUP($G11,$C$505:$O$1001,13,0),0) -> 0 | K11: Practice | L11: Cloud | M11: Consulting | N11: PvtPubCloud | O11: Administrator | P11: Architect | Q11: Developer | R11: TechnicalLead | S11: ConsultantCloud | T11: ECM | U11: SharePoint | V11: AdministratorSharepoint | W11: ArchitectSharepoint | X11: DeveloperSharepoint | Y11: TechnicalLeadSharepoint | Z11: TestLeadShaerpoint | AA11: TesterSharepoint | AB11: IMS | AC11: ArchitectIMS | AD11: IMSArchitect | AE11: BuildandReleaseManagement | AF11: BuildManager | AG11: InfoSecurity | AH11: ConsultantInfoSec | AI11: ITSM | AJ11: ConsultantITSM | AK11: Management | AL11: ProgramManagerManagement | AM11: ProjectManagerManagement | AN11: Middleware | AO11: AdministratorMiddleware | AP11: Network | AQ11: AdministratorNetwork | AR11: Security | AS11: AdministratorSecurity | AT11: Storage | AU11: AdministratorStorage | AV11: Systems | AW11: AdministratorSystemsSolaris | AX11: AdministratorSystemsVMWareSCCMCitrix | AY11: AdministratorSystemsMSSQLOracle | AZ11: AdministratorSystemsSybase | BA11: AdministratorSystems | BB11: IMSBASIC | BC11: DataCentre | BD11: DataCenterOperations | BE11: Desktop | BF11: DesktopEngineer | BG11: HelpDesk | BH11: HelpDeskAnalyst | BI11: MailSetup | BJ11: Configurator | BK11: NOCDesktop | BL11: DesktopEngineerNOC | BM11: OpsSupport | BN11: OpnSupportIMSBASIC | BO11: Telecom | BP11: Technician | BQ11: IT | BR11: ADS | BS11: BusinessSystemsAnalyst | BT11: Domain | BU11: BusinessAnalyst | BV11: DuckCreek | BW11: ArchitectDuckCreek | BX11: ProjectManagerDuckCreek | BY11: Generic | BZ11: DatabaseAdministratorIMSGeneric | CA11: DeveloperGoldenSource | CB11: Intergration | CC11: ConsultantITIL | CD11: JavaNet | CE11: ArchitectJavaNet | CF11: JavaNetColdFusion | CG11: DeveloperJavaNetColdFusion | CH11: Lotus Notes | CI11: DeveloperLotusNotes | CJ11: Mainframe | CK11: DeveloperMainframe | CL11: ManagementIT | CM11: ProjectManagerIT | CN11: Operation | CO11: Others | CP11: TechnicalWriter | CQ11: TumbleWeed | CR11: DeveloperTumbleWeed | CS11: Vermillion | CT11: DeveloperVermillion | CU11: Amdocs | CV11: DeveloperAmdocs | CW11: ProjectManagerAmdocs | CX11: JavaNetColdFusionIT | CY11: TechnicalLeadJavaNetColdFusion | CZ11: Remedy | DA11: DeveloperRemedy | DB11: SQL | DC11: DeveloperSQL | DD11: LatentZero | DE11: DeveloperLatentZero | DF11: DomainIT | DG11: ConsultantDomain | DH11: Mobility | DI11: MobilityE | DJ11: ArchitectMobility | DK11: DeveloperMobility | DL11: TechnicalLeadMobility | DM11: SAP | DN11: SAPABAP | DO11: TechnicalABAP | DP11: SAPBasis | DQ11: TechnicalBasis | DR11: SAPDomain | DS11: FunctionalDomain | DT11: SAPManagement | DU11: ProjectManagerSAPManagement | DV11: SOG | DW11: ASG | DX11: ArchitectASG | DY11: BIDW | DZ11: AdministratorBIDW | EA11: ArchitectBIDW | EB11: DeveloperBIDWCognos | EC11: DeveloperBIDW | ED11: DeveloperBIDWETL | EE11: DeveloperBIDWInformatica | EF11: DeveloperBIDWReporting | EG11: ProjectManagerBIDW | EH11: TechnicalLeadAbinitioInformaticaDatastage | EI11: TechnicalLeadActuateCrystal | EJ11: TechnicalLeadMicrostrategyAbinitioTeradata | EK11: TechnicalLeadCognosBO | EL11: TechnicalLeadReporting | EM11: TesterBIDW | EN11: EAI | EO11: AnalystBusinessRules | EP11: ArchitectTIBCO | EQ11: ArchitectEAI | ER11: ArchitectBusinessRules | ES11: ArchitectProcess | ET11: ConfiguratorMercatorMQ | EU11: ConsultantTIBCO | EV11: DeveloperEAI | EW11: DeveloperIBMWebSphereProcessServer | EX11: DeveloperIBMWebSphereMessageBroker | EY11: DeveloperTibco | EZ11: DeveloperWebApplicationIntegrationMiddlewareInfrastructure | FA11: DeveloperWebMethods | FB11: DeveloperBusinessRules | FC11: ProjectManagerEAI | FD11: TechnicalLeadEAI | FE11: Oracle | FF11: DatabaseAdministratorOracle | FG11: DeveloperOracle | FH11: FunctionalOracle | FI11: ProjectManagerOracle | FJ11: TechnicalOracle | FK11: Peoplesoft | FL11: FunctionalPeoplesoft | FM11: ProjectManagerPeoplesoft | FN11: TechnicalPeoplesoft | FO11: ConsultantPeoplesoft | FP11: SOGTWO | FQ11: Varicent | FR11: DeveloperVaricent | FS11: Testing | FT11: Automation | FU11: DomainTesting | FV11: ManualTesting | FW11: Performance | FX11: TestingTwo | FY11: ProductBased | FZ11: AutomationTester | GA11: AutomationTestLead | GB11: AutomationTestManager | GC11: DomainTestBusinessAnalyst | GD11: ManualTestingTester | GE11: ManualTestingTestLead | GF11: ManualTestingTestManager | GG11: PerformanceTester | GH11: PerformanceTestLead | GI11: PerformanceTestManager | GJ11: ProductBasedTester | GK11: ProductBasedTestLead | GL11: ProductBasedTestManager | GM11: PLMEnggServices | GN11: PLM | GO11: PLMDeveloper | GP11: PLMTechnicalLead | GQ11: PLMAdministrator | GR11: PLMDesigner | GS11: PLMProjectManager | GT11: PLMEnggServices | GU11: EnggServices | GV11: EnggServicesAnalyst | GW11: EnggServicesProject Lead | GX11: EnggServicesDeveloper | GY11: EnggServicesDesigner | GZ11: EnggServicesProjectManager | HA11: SAPone | HB11: SAPArchitect | HC11: IMSGeneric | HD11: Integrator | HE11: DeveloperEDI | HF11: EDI | HG11: PEGA | HH11: PEGAEAI | HI11: PEGALeadSystemArchitect | HJ11: PEGAProjectManager | HK11: PEGASeniorArchitect | HL11: PEGAArchitect | HM11: PEGADeveloper | HP11: =+'Staffing-Roles'!DS119 -> 0 | HQ11: =+'Staffing-Roles'!DS146 -> 0 | HR11: =+HP11*$HR$3 -> 0 | HS11: =+HQ11*$HS$3 -> 0 | HT11: =+HR11*I11 -> 0 | HU11: =+HS11*J11 -> 0 | HV11: =+HT11+HU11 -> 0 | HX11: =+(HP11*$HX$3)*I11 -> 0 | HY11: =+(HQ11*$HY$3)*J11 -> 0 | HZ11: =+HX11+HY11 -> 0
A12: =+A11+1 -> 7 | F12: =+B12&"/"&C12&"/"&D12&"/"&E12 -> /// | G12: =VLOOKUP($F12,$Q$101:$T$1500,3,0) -> 0 | H12: =+IFERROR(VLOOKUP($G12,$C$505:$O$1001,13,0),0) -> 0 | BQ12: Domain | FK12: DatabaseAdministratorPeoplesoft | GN12: PLMDeveloper | GU12: EnggServicesAnalyst | HP12: =+'Staffing-Roles'!DS120 -> 0 | HQ12: =+'Staffing-Roles'!DS147 -> 0 | HR12: =+HP12*$HR$3 -> 0 | HS12: =+HQ12*$HS$3 -> 0 | HT12: =+HR12*I12 -> 0 | HU12: =+HS12*J12 -> 0 | HV12: =+HT12+HU12 -> 0 | HX12: =+(HP12*$HX$3)*I12 -> 0 | HY12: =+(HQ12*$HY$3)*J12 -> 0 | HZ12: =+HX12+HY12 -> 0
A13: =+A12+1 -> 8 | F13: =+B13&"/"&C13&"/"&D13&"/"&E13 -> /// | G13: =VLOOKUP($F13,$Q$101:$T$1500,3,0) -> 0 | H13: =+IFERROR(VLOOKUP($G13,$C$505:$O$1001,13,0),0) -> 0 | K13: Cloud | L13: Consulting | M13: ConsultantCloud | N13: Administrator | O13: Junior | P13: Junior | Q13: Junior | R13: Junior | S13: Junior | T13: SharePoint | U13: AdministratorSharepoint | V13: Junior | W13: Junior | X13: Junior | Y13: Junior | Z13: Junior | AA13: Junior | AB13: ArchitectIMS | AC13: IMSArchitect | AD13: Junior | AE13: BuildManager | AF13: Junior | AG13: ConsultantInfoSec | AH13: Junior | AI13: ConsultantITSM | AJ13: Junior | AK13: ProgramManagerManagement | AL13: Junior | AM13: Junior | AN13: AdministratorMiddleware | AO13: Junior | AP13: AdministratorNetwork | AQ13: Junior | AR13: AdministratorSecurity | AS13: Junior | AT13: AdministratorStorage | AU13: Junior | AV13: AdministratorSystemsSolaris | AW13: Junior | AX13: Junior | AY13: Junior | AZ13: Junior | BA13: Junior | BB13: DataCentre | BC13: DataCenterOperations | BD13: Junior | BE13: DesktopEngineer | BF13: Junior | BG13: HelpDeskAnalyst | BH13: Junior | BI13: Configurator | BJ13: Junior | BK13: DesktopEngineerNOC | BL13: Junior | BM13: OpnSupportIMSBASIC | BN13: Junior | BO13: Technician | BP13: Junior | BQ13: ADS | BR13: BusinessSystemsAnalyst | BS13: Junior | BT13: BusinessAnalyst | BU13: Junior | BV13: ArchitectDuckCreek | BW13: Junior | BX13: Junior | BY13: ContentEntryAnalyst | BZ13: Junior | CA13: Junior | CB13: IntegrationEngineer | CC13: Junior | CD13: ArchitectJavaNet | CE13: Junior | CF13: DeveloperJavaNetColdFusion | CG13: Junior | CH13: DeveloperLotusNotes | CI13: Junior | CJ13: DeveloperMainframe | CK13: Junior | CL13: EngagementManagerAccount ManagerProject DirectorProgramController | CM13: Junior | CN13: OperationsAnalyst | CO13: GraphicsDesigner | CP13: Junior | CQ13: DeveloperTumbleWeed | CR13: Junior | CS13: DeveloperVermillion | CT13: Junior | CU13: DeveloperAmdocs | CV13: Junior | CW13: Junior | CX13: TechnicalLeadJavaNetColdFusion | CY13: Junior | CZ13: DeveloperRemedy | DA13: Junior | DB13: DeveloperSQL | DC13: Junior | DD13: DeveloperLatentZero | DE13: Junior | DF13: ConsultantDomain | DG13: Junior | DH13: MobilityE | DI13: ArchitectMobility | DJ13: Junior | DK13: Junior | DL13: Junior | DM13: SAPABAP | DN13: TechnicalABAP | DO13: Junior | DP13: TechnicalBasis | DQ13: Junior | DR13: FunctionalDomain | DS13: Junior | DT13: ProjectManagerSAPManagement | DU13: Junior | DV13: ASG | DW13: ApplicationArchitect | DX13: ApplicationArchitect | DY13: AdministratorBIDW | DZ13: Junior | EA13: Junior | EB13: Junior | EC13: Junior | ED13: Junior | EE13: Junior | EF13: Junior | EG13: Junior | EH13: Junior | EI13: Junior | EJ13: Junior | EK13: Junior | EL13: Junior | EM13: Junior | EN13: AnalystBusinessRules | EO13: Junior | EP13: Junior | EQ13: Junior | ER13: Junior | ES13: Junior | ET13: Junior | EU13: Junior | EV13: Junior | EW13: Junior | EX13: Junior | EY13: Junior | EZ13: Junior | FA13: Junior | FB13: Junior | FC13: Junior | FD13: Junior | FE13: DatabaseAdministratorOracle | FF13: Junior | FG13: Junior | FH13: Junior | FI13: Junior | FJ13: Junior | FK13: FunctionalPeoplesoft | FL13: Junior | FM13: Junior | FN13: Junior | FO13: Junior | FP13: ConsultantUsabilitySpecialist | FQ13: DeveloperVaricent | FR13: Junior | FS13: Automation | FT13: AutomationTester | FU13: DomainTestBusinessAnalyst | FV13: ManualTestingTester | FW13: PerformanceTester | FX13: TestingTestDirector | FY13: ProductBasedTester | FZ13: Junior | GA13: Junior | GB13: Junior | GC13: Junior | GD13: Junior | GE13: Junior | GF13: Junior | GG13: Junior | GH13: Junior | GI13: Junior | GJ13: Junior | GK13: Junior | GL13: Junior | GM13: PLM | GN13: PLMTechnicalLead | GO13: Junior | GP13: Junior | GQ13: Junior | GR13: Junior | GS13: Junior | GT13: EnggServices | GU13: EnggServicesProject Lead | GV13: Junior | GW13: Junior | GX13: Junior | GY13: Junior | GZ13: Junior | HA13: SAPArchitect | HB13: Junior | HC13: DatabaseAdministratorIMSGeneric | HD13: Junior | HE13: Junior | HF13: DeveloperEDI | HG13: PEGAEAI | HH13: PEGALeadSystemArchitect | HI13: Senior | HJ13: Junior | HK13: Junior | HL13: Senior | HM13: Junior | HP13: =+'Staffing-Roles'!DS121 -> 0 | HQ13: =+'Staffing-Roles'!DS148 -> 0 | HR13: =+HP13*$HR$3 -> 0 | HS13: =+HQ13*$HS$3 -> 0 | HT13: =+HR13*I13 -> 0 | HU13: =+HS13*J13 -> 0 | HV13: =+HT13+HU13 -> 0 | HX13: =+(HP13*$HX$3)*I13 -> 0 | HY13: =+(HQ13*$HY$3)*J13 -> 0 | HZ13: =+HX13+HY13 -> 0
A14: =+A13+1 -> 9 | F14: =+B14&"/"&C14&"/"&D14&"/"&E14 -> /// | G14: =VLOOKUP($F14,$Q$101:$T$1500,3,0) -> 0 | H14: =+IFERROR(VLOOKUP($G14,$C$505:$O$1001,13,0),0) -> 0 | K14: ECM | L14: PvtPubCloud | N14: Architect | O14: MidLevel | P14: MidLevel | Q14: MidLevel | R14: Senior | S14: MidLevel | T14: Collaboration | U14: ArchitectSharepoint | V14: MidLevel | W14: MidLevel | X14: MidLevel | Y14: Senior | Z14: Senior | AA14: Senior | AB14: BuildandReleaseManagement | AD14: Midlevel | AF14: MidLevel | AH14: MidLevel | AJ14: MidLevel | AK14: ProjectManagerManagement | AL14: MidLevel | AM14: MidLevel | AO14: MidLevel | AQ14: MidLevel | AS14: MidLevel | AU14: MidLevel | AV14: AdministratorSystemsVMWareSCCMCitrix | AW14: MidLevel | AX14: MidLevel | AY14: MidLevel | AZ14: MidLevel | BA14: MidLevel | BB14: Desktop | BD14: MidLevel | BF14: MidLevel | BH14: Senior | BJ14: MidLevel | BL14: MidLevel | BN14: Senior | BP14: MidLevel | BQ14: DuckCreek | BS14: MidLevel | BU14: MidLevel | BV14: Configurator | BW14: MidLevel | BX14: MidLevel | BZ14: MidLevel | CA14: MidLevel | CB14: IntegrationSpecialist | CC14: MidLevel | CE14: MidLevel | CF14: TechnicalLeadJavaNetColdFusion | CG14: MidLevel | CI14: MidLevel | CK14: MidLevel | CL14: ProjectManagerIT | CM14: MidLevel | CN14: ProcessLeader | CO14: TechnicalWriter | CP14: MidLevel | CR14: MidLevel | CT14: MidLevel | CU14: ProjectManagerAmdocs | CV14: MidLevel | CW14: MidLevel | CY14: Senior | DA14: MidLevel | DC14: MidLevel | DE14: MidLevel | DG14: MidLevel | DI14: DeveloperMobility | DJ14: MidLevel | DK14: MidLevel | DL14: Senior | DM14: SAPBasis | DO14: MidLevel | DQ14: MidLevel | DS14: MidLevel | DU14: MidLevel | DV14: BIDW | DW14: SolutionArchitect | DX14: SolutionArchitect | DY14: ArchitectBIDW | DZ14: MidLevel | EA14: MidLevel | EB14: MidLevel | EC14: MidLevel | ED14: MidLevel | EE14: MidLevel | EF14: MidLevel | EG14: MidLevel | EH14: Senior | EI14: Senior | EJ14: Senior | EK14: Senior | EL14: Senior | EM14: Senior | EN14: ArchitectTIBCO | EO14: MidLevel | EP14: MidLevel | EQ14: MidLevel | ER14: MidLevel | ES14: MidLevel | ET14: MidLevel | EU14: MidLevel | EW14: MidLevel | EX14: MidLevel | EY14: MidLevel | EZ14: MidLevel | FA14: MidLevel | FB14: MidLevel | FC14: MidLevel | FD14: Senior | FE14: DeveloperOracle | FF14: MidLevel | FG14: MidLevel | FH14: MidLevel | FI14: MidLevel | FJ14: MidLevel | FK14: ProjectManagerPeoplesoft | FL14: MidLevel | FM14: MidLevel | FN14: MidLevel | FO14: MidLevel | FP14: DataAdministratorProcess AnalystSOG | FR14: MidLevel | FS14: DomainTesting | FT14: AutomationTestLead | FV14: ManualTestingTestLead | FW14: PerformanceTestLead | FX14: TestingTestProcessConsultant | FY14: ProductBasedTestLead | FZ14: MidLevel | GA14: Senior | GB14: MidLevel | GC14: Senior | GD14: MidLevel | GE14: Senior | GF14: MidLevel | GG14: MidLevel | GH14: Senior | GI14: MidLevel | GJ14: Senior | GK14: Senior | GL14: MidLevel | GM14: EnggServices | GN14: PLMAdministrator | GO14: MidLevel | GP14: Senior | GQ14: MidLevel | GR14: Senior | GS14: MidLevel | GU14: EnggServicesDeveloper | GV14: MidLevel | GW14: Senior | GX14: MidLevel | GY14: Senior | GZ14: MidLevel | HB14: MidLevel | HD14: MidLevel | HE14: MidLevel | HH14: PEGAProjectManager | HJ14: MidLevel | HK14: MidLevel | HL14: Junior | HP14: =+'Staffing-Roles'!DS122 -> 0 | HQ14: =+'Staffing-Roles'!DS149 -> 0 | HR14: =+HP14*$HR$3 -> 0 | HS14: =+HQ14*$HS$3 -> 0 | HT14: =+HR14*I14 -> 0 | HU14: =+HS14*J14 -> 0 | HV14: =+HT14+HU14 -> 0 | HX14: =+(HP14*$HX$3)*I14 -> 0 | HY14: =+(HQ14*$HY$3)*J14 -> 0 | HZ14: =+HX14+HY14 -> 0
A15: =+A14+1 -> 10 | F15: =+B15&"/"&C15&"/"&D15&"/"&E15 -> /// | G15: =VLOOKUP($F15,$Q$101:$T$1500,3,0) -> 0 | H15: =+IFERROR(VLOOKUP($G15,$C$505:$O$1001,13,0),0) -> 0 | K15: IMS | N15: Developer | O15: Senior | P15: Senior | Q15: Senior | S15: Senior | T15: Customer_Communication_Management | U15: DeveloperSharepoint | V15: Senior | W15: Senior | X15: Senior | AB15: InfoSecurity | AD15: Senior | AF15: Senior | AH15: Senior | AJ15: Senior | AK15: ProgramLeadManagement | AL15: Senior | AM15: Senior | AO15: Senior | AQ15: Senior | AS15: Senior | AU15: Senior | AV15: AdministratorSystemsMSSQLOracle | AW15: Senior | AX15: Senior | AY15: Senior | AZ15: Senior | BA15: Senior | BB15: HelpDesk | BD15: Senior | BF15: Senior | BJ15: Senior | BL15: Senior | BP15: Senior | BQ15: Generic | BS15: Senior | BU15: Senior | BV15: Integrator | BW15: Senior | BX15: Senior | BZ15: Senior | CA15: Senior | CB15: InterfaceDesigner | CC15: Senior | CE15: Senior | CG15: Senior | CI15: Senior | CK15: Senior | CM15: Senior | CO15: TemplateDeveloper | CP15: Senior | CR15: Senior | CT15: Senior | CV15: Senior | CW15: Senior | DA15: Senior | DC15: Senior | DE15: Senior | DG15: Senior | DI15: TechnicalLeadMobility | DJ15: Senior | DK15: Senior | DM15: SAPDomain | DO15: Senior | DQ15: Senior | DS15: Senior | DU15: Senior | DV15: EAI | DW15: EnterpriseArchitect | DX15: EnterpriseArchitect | DY15: DataModelerBIDW | DZ15: Senior | EA15: Senior | EB15: Senior | EC15: Senior | ED15: Senior | EE15: Senior | EF15: Senior | EG15: Senior | EN15: ArchitectEAI | EO15: Senior | EP15: Senior | EQ15: Senior | ER15: Senior | ES15: Senior | ET15: Senior | EU15: Senior | EW15: Senior | EX15: Senior | EY15: Senior | EZ15: Senior | FA15: Senior | FB15: Senior | FC15: Senior | FE15: FunctionalOracle | FF15: Senior | FG15: Senior | FH15: Senior | FI15: Senior | FJ15: Senior | FK15: TechnicalPeoplesoft | FL15: Senior | FM15: Senior | FN15: Senior | FO15: Senior | FR15: Senior | FS15: ManualTesting | FT15: AutomationTestManager | FV15: ManualTestingTestManager | FW15: PerformanceTestManager | FY15: ProductBasedTestManager | FZ15: Senior | GB15: Senior | GD15: Senior | GF15: Senior | GG15: Senior | GI15: Senior | GL15: Senior | GN15: PLMDesigner | GO15: Senior | GQ15: Senior | GS15: Senior | GU15: EnggServicesDesigner | GV15: Senior | GX15: Senior | GZ15: Senior | HB15: Senior | HD15: Senior | HE15: Senior | HH15: PEGASeniorArchitect | HJ15: Senior | HK15: Senior | HP15: =+'Staffing-Roles'!DS123 -> 0 | HQ15: =+'Staffing-Roles'!DS150 -> 0 | HR15: =+HP15*$HR$3 -> 0 | HS15: =+HQ15*$HS$3 -> 0 | HT15: =+HR15*I15 -> 0 | HU15: =+HS15*J15 -> 0 | HV15: =+HT15+HU15 -> 0 | HX15: =+(HP15*$HX$3)*I15 -> 0 | HY15: =+(HQ15*$HY$3)*J15 -> 0 | HZ15: =+HX15+HY15 -> 0
A16: =+A15+1 -> 11 | F16: =+B16&"/"&C16&"/"&D16&"/"&E16 -> /// | G16: =VLOOKUP($F16,$Q$101:$T$1500,3,0) -> 0 | H16: =+IFERROR(VLOOKUP($G16,$C$505:$O$1001,13,0),0) -> 0 | K16: IMSBASIC | N16: TechnicalLead | T16: Document_Management | U16: TechnicalLeadSharepoint | AB16: ITSM | AV16: AdministratorSystems | BB16: MailSetup | BQ16: GoldenSource | BV16: ProjectManagerDuckCreek | DM16: SAPManagement | DV16: EDI | DY16: DeveloperBIDWCognos | EN16: ArchitectBusinessRules | FE16: ProjectManagerOracle | FK16: ConsultantPeoplesoft | FS16: Performance | GN16: PLMProjectManager | GU16: EnggServicesProjectManager | HH16: PEGAArchitect | HP16: =+'Staffing-Roles'!DS124 -> 0 | HQ16: =+'Staffing-Roles'!DS151 -> 0 | HR16: =+HP16*$HR$3 -> 0 | HS16: =+HQ16*$HS$3 -> 0 | HT16: =+HR16*I16 -> 0 | HU16: =+HS16*J16 -> 0 | HV16: =+HT16+HU16 -> 0 | HX16: =+(HP16*$HX$3)*I16 -> 0 | HY16: =+(HQ16*$HY$3)*J16 -> 0 | HZ16: =+HX16+HY16 -> 0
A17: =+A16+1 -> 12 | F17: =+B17&"/"&C17&"/"&D17&"/"&E17 -> /// | G17: =VLOOKUP($F17,$Q$101:$T$1500,3,0) -> 0 | H17: =+IFERROR(VLOOKUP($G17,$C$505:$O$1001,13,0),0) -> 0 | K17: IT | T17: Imaging_and_Scanning | U17: TestLeadShaerpoint | AB17: Management | AV17: AdministratorSystemsSybase | BB17: NOCDesktop | BQ17: ITIL | DM17: SAPone | DV17: Oracle | DY17: DeveloperBIDW | EN17: ArchitectProcess | FE17: TechnicalOracle | FS17: ProductBased | HH17: PEGADeveloper | HP17: =+'Staffing-Roles'!DS125 -> 0 | HQ17: =+'Staffing-Roles'!DS152 -> 0 | HR17: =+HP17*$HR$3 -> 0 | HS17: =+HQ17*$HS$3 -> 0 | HT17: =+HR17*I17 -> 0 | HU17: =+HS17*J17 -> 0 | HV17: =+HT17+HU17 -> 0 | HX17: =+(HP17*$HX$3)*I17 -> 0 | HY17: =+(HQ17*$HY$3)*J17 -> 0 | HZ17: =+HX17+HY17 -> 0
A18: =+A17+1 -> 13 | F18: =+B18&"/"&C18&"/"&D18&"/"&E18 -> /// | G18: =VLOOKUP($F18,$Q$101:$T$1500,3,0) -> 0 | H18: =+IFERROR(VLOOKUP($G18,$C$505:$O$1001,13,0),0) -> 0 | K18: SOG | T18: Web_Content_Management | U18: TesterSharepoint | AB18: Middleware | BB18: OpsSupport | BQ18: JavaNet | DV18: Peoplesoft | DY18: DeveloperBIDWETL | EN18: ConfiguratorMercatorMQ | FS18: TestingTwo | HP18: =+'Staffing-Roles'!DS126 -> 0 | HQ18: =+'Staffing-Roles'!DS153 -> 0 | HR18: =+HP18*$HR$3 -> 0 | HS18: =+HQ18*$HS$3 -> 0 | HT18: =+HR18*I18 -> 0 | HU18: =+HS18*J18 -> 0 | HV18: =+HT18+HU18 -> 0 | HX18: =+(HP18*$HX$3)*I18 -> 0 | HY18: =+(HQ18*$HY$3)*J18 -> 0 | HZ18: =+HX18+HY18 -> 0
A19: =+A18+1 -> 14 | F19: =+B19&"/"&C19&"/"&D19&"/"&E19 -> /// | G19: =VLOOKUP($F19,$Q$101:$T$1500,3,0) -> 0 | H19: =+IFERROR(VLOOKUP($G19,$C$505:$O$1001,13,0),0) -> 0 | K19: Testing | AB19: Network | BB19: Telecom | BQ19: JavaNetColdFusionIT | DV19: SOGTWO | DY19: DeveloperBIDWInformatica | EN19: ConsultantTIBCO | HP19: =+'Staffing-Roles'!DS127 -> 0 | HQ19: =+'Staffing-Roles'!DS154 -> 0 | HR19: =+HP19*$HR$3 -> 0 | HS19: =+HQ19*$HS$3 -> 0 | HT19: =+HR19*I19 -> 0 | HU19: =+HS19*J19 -> 0 | HV19: =+HT19+HU19 -> 0 | HX19: =+(HP19*$HX$3)*I19 -> 0 | HY19: =+(HQ19*$HY$3)*J19 -> 0 | HZ19: =+HX19+HY19 -> 0
A20: =+A19+1 -> 15 | F20: =+B20&"/"&C20&"/"&D20&"/"&E20 -> /// | G20: =VLOOKUP($F20,$Q$101:$T$1500,3,0) -> 0 | H20: =+IFERROR(VLOOKUP($G20,$C$505:$O$1001,13,0),0) -> 0 | K20: Mobility | AB20: Security | BQ20: LotusNotes | DV20: SAPABAP | DY20: DeveloperBIDWReporting | EN20: DeliveryManagerEIS | HP20: =+'Staffing-Roles'!DS128 -> 0 | HQ20: =+'Staffing-Roles'!DS155 -> 0 | HR20: =+HP20*$HR$3 -> 0 | HS20: =+HQ20*$HS$3 -> 0 | HT20: =+HR20*I20 -> 0 | HU20: =+HS20*J20 -> 0 | HV20: =+HT20+HU20 -> 0 | HX20: =+(HP20*$HX$3)*I20 -> 0 | HY20: =+(HQ20*$HY$3)*J20 -> 0 | HZ20: =+HX20+HY20 -> 0
A21: =+A20+1 -> 16 | F21: =+B21&"/"&C21&"/"&D21&"/"&E21 -> /// | G21: =VLOOKUP($F21,$Q$101:$T$1500,3,0) -> 0 | H21: =+IFERROR(VLOOKUP($G21,$C$505:$O$1001,13,0),0) -> 0 | K21: PLMEnggServices | AB21: Storage | BQ21: Mainframe | DV21: SAPBasis | DY21: ProjectManagerBIDW | EN21: DeveloperIBMWebSphereProcessServer | HP21: =+'Staffing-Roles'!DS129 -> 0 | HQ21: =+'Staffing-Roles'!DS156 -> 0 | HR21: =+HP21*$HR$3 -> 0 | HS21: =+HQ21*$HS$3 -> 0 | HT21: =+HR21*I21 -> 0 | HU21: =+HS21*J21 -> 0 | HV21: =+HT21+HU21 -> 0 | HX21: =+(HP21*$HX$3)*I21 -> 0 | HY21: =+(HQ21*$HY$3)*J21 -> 0 | HZ21: =+HX21+HY21 -> 0
A22: =+A21+1 -> 17 | F22: =+B22&"/"&C22&"/"&D22&"/"&E22 -> /// | G22: =VLOOKUP($F22,$Q$101:$T$1500,3,0) -> 0 | H22: =+IFERROR(VLOOKUP($G22,$C$505:$O$1001,13,0),0) -> 0 | K22: PEGA | AB22: Systems | BQ22: ManagementIT | DV22: SAPDomain | DY22: TechnicalLeadAbinitioInformaticaDatastage | EN22: DeveloperIBMWebSphereMessageBroker | HP22: =+'Staffing-Roles'!DS130 -> 0 | HQ22: =+'Staffing-Roles'!DS157 -> 0 | HR22: =+HP22*$HR$3 -> 0 | HS22: =+HQ22*$HS$3 -> 0 | HT22: =+HR22*I22 -> 0 | HU22: =+HS22*J22 -> 0 | HV22: =+HT22+HU22 -> 0 | HX22: =+(HP22*$HX$3)*I22 -> 0 | HY22: =+(HQ22*$HY$3)*J22 -> 0 | HZ22: =+HX22+HY22 -> 0
A23: =+A22+1 -> 18 | F23: =+B23&"/"&C23&"/"&D23&"/"&E23 -> /// | G23: =VLOOKUP($F23,$Q$101:$T$1500,3,0) -> 0 | H23: =+IFERROR(VLOOKUP($G23,$C$505:$O$1001,13,0),0) -> 0 | AB23: IMSGeneric | BQ23: Operation | DV23: SAPManagement | DY23: TechnicalLeadActuateCrystal | EN23: DeveloperTibco | HP23: =+'Staffing-Roles'!DS131 -> 0 | HQ23: =+'Staffing-Roles'!DS158 -> 0 | HR23: =+HP23*$HR$3 -> 0 | HS23: =+HQ23*$HS$3 -> 0 | HT23: =+HR23*I23 -> 0 | HU23: =+HS23*J23 -> 0 | HV23: =+HT23+HU23 -> 0 | HX23: =+(HP23*$HX$3)*I23 -> 0 | HY23: =+(HQ23*$HY$3)*J23 -> 0 | HZ23: =+HX23+HY23 -> 0
A24: =+A23+1 -> 19 | F24: =+B24&"/"&C24&"/"&D24&"/"&E24 -> /// | G24: =VLOOKUP($F24,$Q$101:$T$1500,3,0) -> 0 | H24: =+IFERROR(VLOOKUP($G24,$C$505:$O$1001,13,0),0) -> 0 | BQ24: Others | DV24: SAPone | DY24: TechnicalLeadMicrostrategyAbinitioTeradata | EN24: DeveloperWebApplicationIntegrationMiddlewareInfrastructure | HP24: =+'Staffing-Roles'!DS132 -> 0 | HQ24: =+'Staffing-Roles'!DS159 -> 0 | HR24: =+HP24*$HR$3 -> 0 | HS24: =+HQ24*$HS$3 -> 0 | HT24: =+HR24*I24 -> 0 | HU24: =+HS24*J24 -> 0 | HV24: =+HT24+HU24 -> 0 | HX24: =+(HP24*$HX$3)*I24 -> 0 | HY24: =+(HQ24*$HY$3)*J24 -> 0 | HZ24: =+HX24+HY24 -> 0
A25: =+A24+1 -> 20 | F25: =+B25&"/"&C25&"/"&D25&"/"&E25 -> /// | G25: =VLOOKUP($F25,$Q$101:$T$1500,3,0) -> 0 | H25: =+IFERROR(VLOOKUP($G25,$C$505:$O$1001,13,0),0) -> 0 | BQ25: TumbleWeed | DV25: Intergration | DY25: TechnicalLeadCognosBO | EN25: DeveloperWebMethods | HP25: =+'Staffing-Roles'!DS133 -> 0 | HQ25: =+'Staffing-Roles'!DS160 -> 0 | HR25: =+HP25*$HR$3 -> 0 | HS25: =+HQ25*$HS$3 -> 0 | HT25: =+HR25*I25 -> 0 | HU25: =+HS25*J25 -> 0 | HV25: =+HT25+HU25 -> 0 | HX25: =+(HP25*$HX$3)*I25 -> 0 | HY25: =+(HQ25*$HY$3)*J25 -> 0 | HZ25: =+HX25+HY25 -> 0
A26: =+A25+1 -> 21 | F26: =+B26&"/"&C26&"/"&D26&"/"&E26 -> /// | G26: =VLOOKUP($F26,$Q$101:$T$1500,3,0) -> 0 | H26: =+IFERROR(VLOOKUP($G26,$C$505:$O$1001,13,0),0) -> 0 | BQ26: Vermillion | DV26: EDI | DY26: TechnicalLeadReporting | EN26: DeveloperBusinessRules | HP26: =+'Staffing-Roles'!DS134 -> 0 | HQ26: =+'Staffing-Roles'!DS161 -> 0 | HR26: =+HP26*$HR$3 -> 0 | HS26: =+HQ26*$HS$3 -> 0 | HT26: =+HR26*I26 -> 0 | HU26: =+HS26*J26 -> 0 | HV26: =+HT26+HU26 -> 0 | HX26: =+(HP26*$HX$3)*I26 -> 0 | HY26: =+(HQ26*$HY$3)*J26 -> 0 | HZ26: =+HX26+HY26 -> 0
A27: =+A26+1 -> 22 | F27: =+B27&"/"&C27&"/"&D27&"/"&E27 -> /// | G27: =VLOOKUP($F27,$Q$101:$T$1500,3,0) -> 0 | H27: =+IFERROR(VLOOKUP($G27,$C$505:$O$1001,13,0),0) -> 0 | BQ27: Amdocs | DY27: TesterBIDW | EN27: ModelerBusinessRules
A28: =+A27+1 -> 23 | F28: =+B28&"/"&C28&"/"&D28&"/"&E28 -> /// | G28: =VLOOKUP($F28,$Q$101:$T$1500,3,0) -> 0 | H28: =+IFERROR(VLOOKUP($G28,$C$505:$O$1001,13,0),0) -> 0 | BQ28: Remedy | EN28: ProcessLeadModeler
A29: =+A28+1 -> 24 | F29: =+B29&"/"&C29&"/"&D29&"/"&E29 -> /// | G29: =VLOOKUP($F29,$Q$101:$T$1500,3,0) -> 0 | H29: =+IFERROR(VLOOKUP($G29,$C$505:$O$1001,13,0),0) -> 0 | BQ29: SQL | EN29: ProgramManagerEIS
A30: =+A29+1 -> 25 | F30: =+B30&"/"&C30&"/"&D30&"/"&E30 -> /// | G30: =VLOOKUP($F30,$Q$101:$T$1500,3,0) -> 0 | H30: =+IFERROR(VLOOKUP($G30,$C$505:$O$1001,13,0),0) -> 0 | BQ30: LatentZero | EN30: ProjectManagerEAI
A31: =+A30+1 -> 26 | F31: =+B31&"/"&C31&"/"&D31&"/"&E31 -> /// | G31: =VLOOKUP($F31,$Q$101:$T$1500,3,0) -> 0 | H31: =+IFERROR(VLOOKUP($G31,$C$505:$O$1001,13,0),0) -> 0 | BQ31: DomainIT | EN31: TechnicalLeadEAI
A32: =+A31+1 -> 27 | F32: =+B32&"/"&C32&"/"&D32&"/"&E32 -> /// | G32: =VLOOKUP($F32,$Q$101:$T$1500,3,0) -> 0 | H32: =+IFERROR(VLOOKUP($G32,$C$505:$O$1001,13,0),0) -> 0 | BQ32: Varicent
A33: =+A32+1 -> 28 | F33: =+B33&"/"&C33&"/"&D33&"/"&E33 -> /// | G33: =VLOOKUP($F33,$Q$101:$T$1500,3,0) -> 0 | H33: =+IFERROR(VLOOKUP($G33,$C$505:$O$1001,13,0),0) -> 0
A34: =+A33+1 -> 29 | F34: =+B34&"/"&C34&"/"&D34&"/"&E34 -> /// | G34: =VLOOKUP($F34,$Q$101:$T$1500,3,0) -> 0 | H34: =+IFERROR(VLOOKUP($G34,$C$505:$O$1001,13,0),0) -> 0
A35: =+A34+1 -> 30 | F35: =+B35&"/"&C35&"/"&D35&"/"&E35 -> /// | G35: =VLOOKUP($F35,$Q$101:$T$1500,3,0) -> 0 | H35: =+IFERROR(VLOOKUP($G35,$C$505:$O$1001,13,0),0) -> 0
A36: =+A35+1 -> 31 | F36: =+B36&"/"&C36&"/"&D36&"/"&E36 -> /// | G36: =VLOOKUP($F36,$Q$101:$T$1500,3,0) -> 0 | H36: =+IFERROR(VLOOKUP($G36,$C$505:$O$1001,13,0),0) -> 0
A37: =+A36+1 -> 32 | F37: =+B37&"/"&C37&"/"&D37&"/"&E37 -> /// | G37: =VLOOKUP($F37,$Q$101:$T$1500,3,0) -> 0 | H37: =+IFERROR(VLOOKUP($G37,$C$505:$O$1001,13,0),0) -> 0 | L37: Web_Content_Management | M37: Web_Content_Management_TechnicalArchitect | N37: Web_Content_Management_TechnicalLead | O37: Web_Content_Management_Developer | P37: Document_Management | Q37: Document_Management_TechnicalArchitect | R37: Document_Management_TechnicalLead | S37: Document_Management_Developer | T37: Customer_Communication_Management | U37: Customer_Communication_Management_TechnicalArchitect | V37: Customer_Communication_Management_TechnicalLead | W37: Customer_Communication_Management_Developer | X37: Imaging_and_Scanning | Y37: Imaging_and_Scanning_TechnicalArchitect | Z37: Imaging_and_Scanning_TechnicalLead | AA37: Imaging_and_Scanning_Developer | AB37: Collaboration | AC37: Collaboration_TechnicalArchitect | AD37: Collaboration_TechnicalLead | AE37: Collaboration_Developer
A38: =+A37+1 -> 33 | F38: =+B38&"/"&C38&"/"&D38&"/"&E38 -> /// | G38: =VLOOKUP($F38,$Q$101:$T$1500,3,0) -> 0 | H38: =+IFERROR(VLOOKUP($G38,$C$505:$O$1001,13,0),0) -> 0 | L38: Web_Content_Management_TechnicalArchitect | M38: Junior | N38: Junior | O38: Senior | P38: Document_Management_TechnicalArchitect | Q38: Junior | R38: Junior | S38: Senior | T38: Customer_Communication_Management_TechnicalArchitect | U38: Junior | V38: Junior | W38: Senior | X38: Imaging_and_Scanning_TechnicalArchitect | Y38: Junior | Z38: Junior | AA38: Senior | AB38: Collaboration_TechnicalArchitect | AC38: Junior | AD38: Junior | AE38: Senior
A39: =+A38+1 -> 34 | F39: =+B39&"/"&C39&"/"&D39&"/"&E39 -> /// | G39: =VLOOKUP($F39,$Q$101:$T$1500,3,0) -> 0 | H39: =+IFERROR(VLOOKUP($G39,$C$505:$O$1001,13,0),0) -> 0 | L39: Web_Content_Management_TechnicalLead | M39: Senior | N39: Senior | O39: MidLevel | P39: Document_Management_TechnicalLead | Q39: Senior | R39: Senior | S39: MidLevel | T39: Customer_Communication_Management_TechnicalLead | U39: Senior | V39: Senior | W39: MidLevel | X39: Imaging_and_Scanning_TechnicalLead | Y39: Senior | Z39: Senior | AA39: MidLevel | AB39: Collaboration_TechnicalLead | AC39: Senior | AD39: Senior | AE39: MidLevel
A40: =+A39+1 -> 35 | F40: =+B40&"/"&C40&"/"&D40&"/"&E40 -> /// | G40: =VLOOKUP($F40,$Q$101:$T$1500,3,0) -> 0 | H40: =+IFERROR(VLOOKUP($G40,$C$505:$O$1001,13,0),0) -> 0 | L40: Web_Content_Management_Developer | M40: MidLevel | N40: MidLevel | P40: Document_Management_Developer | Q40: MidLevel | R40: MidLevel | T40: Customer_Communication_Management_Developer | U40: MidLevel | V40: MidLevel | X40: Imaging_and_Scanning_Developer | Y40: MidLevel | Z40: MidLevel | AB40: Collaboration_Developer | AC40: MidLevel | AD40: MidLevel
...

Sheet Staffing-Roles
A1: HeadA | C1: Skillbay/Contract Hires-Onsite
A2: SubHeadA | C2: STAFFING DETAILS
C3: Domestic | E3: =IF(CheckList!P18=46,DS32,"")
C4: Deputed | E4: =IF(CheckList!P18=46,(DS58+DS84+DS110),"") | F4: Jan | G4: Feb | H4: Mar | I4: Apr | J4: May | K4: Jun | L4: Jul | M4: Aug | N4: Sep | O4: Oct | P4: Nov | Q4: Dec | S4: Jan | T4: Feb | U4: Mar | V4: Apr | W4: May | X4: Jun | Y4: Jul | Z4: Aug | AA4: Sep | AB4: Oct | AC4: Nov | AD4: Dec | AF4: Jan | AG4: Feb | AH4: Mar | AI4: Apr | AJ4: May | AK4: Jun | AL4: Jul | AM4: Aug | AN4: Sep | AO4: Oct | AP4: Nov | AQ4: Dec | AS4: Jan | AT4: Feb | AU4: Mar | AV4: Apr | AW4: May | AX4: Jun | AY4: Jul | AZ4: Aug | BA4: Sep | BB4: Oct | BC4: Nov | BD4: Dec | BF4: Jan | BG4: Feb | BH4: Mar | BI4: Apr | BJ4: May | BK4: Jun | BL4: Jul | BM4: Aug | BN4: Sep | BO4: Oct | BP4: Nov | BQ4: Dec | BS4: Jan | BT4: Feb | BU4: Mar | BV4: Apr | BW4: May | BX4: Jun | BY4: Jul | BZ4: Aug | CA4: Sep | CB4: Oct | CC4: Nov | CD4: Dec | CF4: Jan | CG4: Feb | CH4: Mar | CI4: Apr | CJ4: May | CK4: Jun | CL4: Jul | CM4: Aug | CN4: Sep | CO4: Oct | CP4: Nov | CQ4: Dec | CS4: Jan | CT4: Feb | CU4: Mar | CV4: Apr | CW4: May | CX4: Jun | CY4: Jul | CZ4: Aug | DA4: Sep | DB4: Oct | DC4: Nov | DD4: Dec | DF4: Jan | DG4: Feb | DH4: Mar | DI4: Apr | DJ4: May | DK4: Jun | DL4: Jul | DM4: Aug | DN4: Sep | DO4: Oct | DP4: Nov | DQ4: Dec
C5: Offshore | E5: =IF(CheckList!P18=46,DS164,"") | F5: 2019 | G5: =F5 -> 2019 | H5: =G5 -> 2019 | I5: =H5 -> 2019 | J5: =I5 -> 2019 | K5: =J5 -> 2019 | L5: =K5 -> 2019 | M5: =L5 -> 2019 | N5: =M5 -> 2019 | ... R5: =Q5 -> 2019 | S5: =R5+1 -> 2020 | T5: =S5 -> 2020 | U5: =T5 -> 2020 | V5: =U5 -> 2020 | W5: =V5 -> 2020 | X5: =W5 -> 2020 | Y5: =X5 -> 2020 | Z5: =Y5 -> 2020 | AA5: =Z5 -> 2020 | ... AE5: =AD5 -> 2020 | AF5: =AE5+1 -> 2021 | AG5: =AF5 -> 2021 | AH5: =AG5 -> 2021 | AI5: =AH5 -> 2021 | AJ5: =AI5 -> 2021 | AK5: =AJ5 -> 2021 | AL5: =AK5 -> 2021 | AM5: =AL5 -> 2021 | AN5: =AM5 -> 2021 | ... AR5: =AQ5 -> 2021 | AS5: =AR5+1 -> 2022 | AT5: =AS5 -> 2022 | AU5: =AT5 -> 2022 | AV5: =AU5 -> 2022 | AW5: =AV5 -> 2022 | AX5: =AW5 -> 2022 | AY5: =AX5 -> 2022 | AZ5: =AY5 -> 2022 | BA5: =AZ5 -> 2022 | ... BE5: =BD5 -> 2022 | BF5: =BE5+1 -> 2023 | BG5: =BF5 -> 2023 | BH5: =BG5 -> 2023 | BI5: =BH5 -> 2023 | BJ5: =BI5 -> 2023 | BK5: =BJ5 -> 2023 | BL5: =BK5 -> 2023 | BM5: =BL5 -> 2023 | BN5: =BM5 -> 2023 | ... BR5: =BQ5 -> 2023 | BS5: =BR5+1 -> 2024 | BT5: =BS5 -> 2024 | BU5: =BT5 -> 2024 | BV5: =BU5 -> 2024 | BW5: =BV5 -> 2024 | BX5: =BW5 -> 2024 | BY5: =BX5 -> 2024 | BZ5: =BY5 -> 2024 | CA5: =BZ5 -> 2024 | ... CE5: =CD5 -> 2024 | CF5: =CE5+1 -> 2025 | CG5: =CF5 -> 2025 | CH5: =CG5 -> 2025 | CI5: =CH5 -> 2025 | CJ5: =CI5 -> 2025 | CK5: =CJ5 -> 2025 | CL5: =CK5 -> 2025 | CM5: =CL5 -> 2025 | CN5: =CM5 -> 2025 | ... CR5: =CQ5 -> 2025 | CS5: =CR5+1 -> 2026 | CT5: =CS5 -> 2026 | CU5: =CT5 -> 2026 | CV5: =CU5 -> 2026 | CW5: =CV5 -> 2026 | CX5: =CW5 -> 2026 | CY5: =CX5 -> 2026 | CZ5: =CY5 -> 2026 | DA5: =CZ5 -> 2026 | ... DE5: =DD5 -> 2026 | DF5: =DE5+1 -> 2027 | DG5: =DF5 -> 2027 | DH5: =DG5 -> 2027 | DI5: =DH5 -> 2027 | DJ5: =DI5 -> 2027 | DK5: =DJ5 -> 2027 | DL5: =DK5 -> 2027 | DM5: =DL5 -> 2027 | DN5: =DM5 -> 2027 | ... DR5: =DQ5 -> 2027 | DS5: Total | DT5: Total SOG
C6: Onsite - Local (Contractor)
C7: Skillbay/Contract Hires- | G7: =F7 -> 0 | H7: =G7 -> 0 | I7: =H7 -> 0 | J7: =I7 -> 0 | K7: =J7 -> 0 | L7: =K7 -> 0 | M7: =L7 -> 0 | N7: =M7 -> 0 | ... Q7: =P7 -> 0 | S7: =Q7 -> 0 | T7: =S7 -> 0 | U7: =T7 -> 0 | V7: =U7 -> 0 | W7: =V7 -> 0 | X7: =W7 -> 0 | Y7: =X7 -> 0 | Z7: =Y7 -> 0 | AA7: =Z7 -> 0 | ... AD7: =AC7 -> 0 | AF7: =AD7 -> 0 | AG7: =AF7 -> 0 | AH7: =AG7 -> 0 | AI7: =AH7 -> 0 | AJ7: =AI7 -> 0 | AK7: =AJ7 -> 0 | AL7: =AK7 -> 0 | AM7: =AL7 -> 0 | AN7: =AM7 -> 0 | ... AQ7: =AP7 -> 0 | AS7: =AQ7 -> 0 | AT7: =AS7 -> 0 | AU7: =AT7 -> 0 | AV7: =AU7 -> 0 | AW7: =AV7 -> 0 | AX7: =AW7 -> 0 | AY7: =AX7 -> 0 | AZ7: =AY7 -> 0 | BA7: =AZ7 -> 0 | ... BD7: =BC7 -> 0 | BF7: =BD7 -> 0 | BG7: =BF7 -> 0 | BH7: =BG7 -> 0 | BI7: =BH7 -> 0 | BJ7: =BI7 -> 0 | BK7: =BJ7 -> 0 | BL7: =BK7 -> 0 | BM7: =BL7 -> 0 | BN7: =BM7 -> 0 | ... BQ7: =BP7 -> 0 | BS7: =BQ7 -> 0 | BT7: =BS7 -> 0 | BU7: =BT7 -> 0 | BV7: =BU7 -> 0 | BW7: =BV7 -> 0 | BX7: =BW7 -> 0 | BY7: =BX7 -> 0 | BZ7: =BY7 -> 0 | CA7: =BZ7 -> 0 | ... CD7: =CC7 -> 0 | CF7: =CD7 -> 0 | CG7: =CF7 -> 0 | CH7: =CG7 -> 0 | CI7: =CH7 -> 0 | CJ7: =CI7 -> 0 | CK7: =CJ7 -> 0 | CL7: =CK7 -> 0 | CM7: =CL7 -> 0 | CN7: =CM7 -> 0 | ... CQ7: =CP7 -> 0 | CS7: =CQ7 -> 0 | CT7: =CS7 -> 0 | CU7: =CT7 -> 0 | CV7: =CU7 -> 0 | CW7: =CV7 -> 0 | CX7: =CW7 -> 0 | CY7: =CX7 -> 0 | CZ7: =CY7 -> 0 | DA7: =CZ7 -> 0 | ... DD7: =DC7 -> 0 | DF7: =DD7 -> 0 | DG7: =DF7 -> 0 | DH7: =DG7 -> 0 | DI7: =DH7 -> 0 | DJ7: =DI7 -> 0 | DK7: =DJ7 -> 0 | DL7: =DK7 -> 0 | DM7: =DL7 -> 0 | DN7: =DM7 -> 0 | ... DQ7: =DP7 -> 0 | DS7: =SUM(F7:Q7)+SUM(S7:AD7)+SUM(AF7:AQ7)+SUM(AS7:BD7)+SUM(BF7:BQ7)+SUM(BS7:CD7)+SUM(CF7:CQ7)+SUM(CS7:DD7)+SUM(DF7:DQ7) -> 0
C8: Onsite - Local
A9: 1 | B9: 1 | C9: ='Role Selection'!F6 -> IT/JavaNetColdFusionIT/DeveloperJavaNetColdFusion/Junior | D9: ='Role Selection'!HO6 -> 0 | E9: ='Role Selection'!H6 -> B2 AP1 / B2 AP2 (0.6 to 3 yrs) | G9: =F9 -> 0 | H9: =G9 -> 0 | I9: =H9 -> 0 | J9: =I9 -> 0 | K9: =J9 -> 0 | L9: =K9 -> 0 | M9: =L9 -> 0 | N9: =M9 -> 0 | ... Q9: =P9 -> 0 | S9: =+Q9 -> 0 | T9: =S9 -> 0 | U9: =T9 -> 0 | V9: =U9 -> 0 | W9: =V9 -> 0 | X9: =W9 -> 0 | Y9: =X9 -> 0 | Z9: =Y9 -> 0 | AA9: =Z9 -> 0 | ... AD9: =AC9 -> 0 | AF9: =+AD9 -> 0 | AG9: =AF9 -> 0 | AH9: =AG9 -> 0 | AI9: =AH9 -> 0 | AJ9: =AI9 -> 0 | AK9: =AJ9 -> 0 | AL9: =AK9 -> 0 | AM9: =AL9 -> 0 | AN9: =AM9 -> 0 | ... AQ9: =AP9 -> 0 | AS9: =AQ9 -> 0 | AT9: =AS9 -> 0 | AU9: =AT9 -> 0 | AV9: =AU9 -> 0 | AW9: =AV9 -> 0 | AX9: =AW9 -> 0 | AY9: =AX9 -> 0 | AZ9: =AY9 -> 0 | BA9: =AZ9 -> 0 | ... BD9: =BC9 -> 0 | BF9: =BD9 -> 0 | BG9: =BF9 -> 0 | BH9: =BG9 -> 0 | BI9: =BH9 -> 0 | BJ9: =BI9 -> 0 | BK9: =BJ9 -> 0 | BL9: =BK9 -> 0 | BM9: =BL9 -> 0 | BN9: =BM9 -> 0 | ... BQ9: =BP9 -> 0 | BS9: =BQ9 -> 0 | BT9: =BS9 -> 0 | BU9: =BT9 -> 0 | BV9: =BU9 -> 0 | BW9: =BV9 -> 0 | BX9: =BW9 -> 0 | BY9: =BX9 -> 0 | BZ9: =BY9 -> 0 | CA9: =BZ9 -> 0 | ... CD9: =CC9 -> 0 | CF9: =CD9 -> 0 | CG9: =CF9 -> 0 | CH9: =CG9 -> 0 | CI9: =CH9 -> 0 | CJ9: =CI9 -> 0 | CK9: =CJ9 -> 0 | CL9: =CK9 -> 0 | CM9: =CL9 -> 0 | CN9: =CM9 -> 0 | ... CQ9: =CP9 -> 0 | CS9: =CQ9 -> 0 | CT9: =CS9 -> 0 | CU9: =CT9 -> 0 | CV9: =CU9 -> 0 | CW9: =CV9 -> 0 | CX9: =CW9 -> 0 | CY9: =CX9 -> 0 | CZ9: =CY9 -> 0 | DA9: =CZ9 -> 0 | ... DD9: =DC9 -> 0 | DF9: =DD9 -> 0 | DG9: =DF9 -> 0 | DH9: =DG9 -> 0 | DI9: =DH9 -> 0 | DJ9: =DI9 -> 0 | DK9: =DJ9 -> 0 | DL9: =DK9 -> 0 | DM9: =DL9 -> 0 | DN9: =DM9 -> 0 | ... DQ9: =DP9 -> 0 | DS9: =SUM(F9:Q9)+SUM(S9:AD9)+SUM(AF9:AQ9)+SUM(AS9:BD9)+SUM(BF9:BQ9)+SUM(BS9:CD9)+SUM(CF9:CQ9)+SUM(CS9:DD9)+SUM(DF9:DQ9) -> 0
C10: ='Role Selection'!F7 -> /// | D10: ='Role Selection'!HO7 -> 0 | E10: ='Role Selection'!H7 -> 0 | G10: =F10 -> 0 | H10: =G10 -> 0 | I10: =H10 -> 0 | J10: =I10 -> 0 | K10: =J10 -> 0 | L10: =K10 -> 0 | M10: =L10 -> 0 | N10: =M10 -> 0 | ... Q10: =P10 -> 0 | S10: =+Q10 -> 0 | T10: =S10 -> 0 | U10: =T10 -> 0 | V10: =U10 -> 0 | W10: =V10 -> 0 | X10: =W10 -> 0 | Y10: =X10 -> 0 | Z10: =Y10 -> 0 | AA10: =Z10 -> 0 | ... AD10: =AC10 -> 0 | AF10: =AD10 -> 0 | AG10: =AF10 -> 0 | AH10: =AG10 -> 0 | AI10: =AH10 -> 0 | AJ10: =AI10 -> 0 | AK10: =AJ10 -> 0 | AL10: =AK10 -> 0 | AM10: =AL10 -> 0 | AN10: =AM10 -> 0 | ... AQ10: =AP10 -> 0 | AS10: =AQ10 -> 0 | AT10: =AS10 -> 0 | AU10: =AT10 -> 0 | AV10: =AU10 -> 0 | AW10: =AV10 -> 0 | AX10: =AW10 -> 0 | AY10: =AX10 -> 0 | AZ10: =AY10 -> 0 | BA10: =AZ10 -> 0 | ... BD10: =BC10 -> 0 | BF10: =BD10 -> 0 | BG10: =BF10 -> 0 | BH10: =BG10 -> 0 | BI10: =BH10 -> 0 | BJ10: =BI10 -> 0 | BK10: =BJ10 -> 0 | BL10: =BK10 -> 0 | BM10: =BL10 -> 0 | BN10: =BM10 -> 0 | ... BQ10: =BP10 -> 0 | BS10: =BQ10 -> 0 | BT10: =BS10 -> 0 | BU10: =BT10 -> 0 | BV10: =BU10 -> 0 | BW10: =BV10 -> 0 | BX10: =BW10 -> 0 | BY10: =BX10 -> 0 | BZ10: =BY10 -> 0 | CA10: =BZ10 -> 0 | ... CD10: =CC10 -> 0 | CF10: =CD10 -> 0 | CG10: =CF10 -> 0 | CH10: =CG10 -> 0 | CI10: =CH10 -> 0 | CJ10: =CI10 -> 0 | CK10: =CJ10 -> 0 | CL10: =CK10 -> 0 | CM10: =CL10 -> 0 | CN10: =CM10 -> 0 | ... CQ10: =CP10 -> 0 | CS10: =CQ10 -> 0 | CT10: =CS10 -> 0 | CU10: =CT10 -> 0 | CV10: =CU10 -> 0 | CW10: =CV10 -> 0 | CX10: =CW10 -> 0 | CY10: =CX10 -> 0 | CZ10: =CY10 -> 0 | DA10: =CZ10 -> 0 | ... DD10: =DC10 -> 0 | DF10: =DD10 -> 0 | DG10: =DF10 -> 0 | DH10: =DG10 -> 0 | DI10: =DH10 -> 0 | DJ10: =DI10 -> 0 | DK10: =DJ10 -> 0 | DL10: =DK10 -> 0 | DM10: =DL10 -> 0 | DN10: =DM10 -> 0 | ... DQ10: =DP10 -> 0 | DS10: =SUM(F10:Q10)+SUM(S10:AD10)+SUM(AF10:AQ10)+SUM(AS10:BD10)+SUM(BF10:BQ10)+SUM(BS10:CD10)+SUM(CF10:CQ10)+SUM(CS10:DD10)+SUM(DF10:DQ10) -> 0
A11: 1 | B11: 2 | C11: ='Role Selection'!F8 -> /// | D11: ='Role Selection'!HO8 -> 0 | E11: ='Role Selection'!H8 -> 0 | G11: =F11 -> 0 | H11: =G11 -> 0 | I11: =H11 -> 0 | J11: =I11 -> 0 | K11: =J11 -> 0 | L11: =K11 -> 0 | M11: =L11 -> 0 | N11: =M11 -> 0 | ... Q11: =P11 -> 0 | S11: =+Q11 -> 0 | T11: =S11 -> 0 | U11: =T11 -> 0 | V11: =U11 -> 0 | W11: =V11 -> 0 | X11: =W11 -> 0 | Y11: =X11 -> 0 | Z11: =Y11 -> 0 | AA11: =Z11 -> 0 | ... AD11: =AC11 -> 0 | AF11: =AD11 -> 0 | AG11: =AF11 -> 0 | AH11: =AG11 -> 0 | AI11: =AH11 -> 0 | AJ11: =AI11 -> 0 | AK11: =AJ11 -> 0 | AL11: =AK11 -> 0 | AM11: =AL11 -> 0 | AN11: =AM11 -> 0 | ... AQ11: =AP11 -> 0 | AS11: =AQ11 -> 0 | AT11: =AS11 -> 0 | AU11: =AT11 -> 0 | AV11: =AU11 -> 0 | AW11: =AV11 -> 0 | AX11: =AW11 -> 0 | AY11: =AX11 -> 0 | AZ11: =AY11 -> 0 | BA11: =AZ11 -> 0 | ... BD11: =BC11 -> 0 | BF11: =BD11 -> 0 | BG11: =BF11 -> 0 | BH11: =BG11 -> 0 | BI11: =BH11 -> 0 | BJ11: =BI11 -> 0 | BK11: =BJ11 -> 0 | BL11: =BK11 -> 0 | BM11: =BL11 -> 0 | BN11: =BM11 -> 0 | ... BQ11: =BP11 -> 0 | BS11: =BQ11 -> 0 | BT11: =BS11 -> 0 | BU11: =BT11 -> 0 | BV11: =BU11 -> 0 | BW11: =BV11 -> 0 | BX11: =BW11 -> 0 | BY11: =BX11 -> 0 | BZ11: =BY11 -> 0 | CA11: =BZ11 -> 0 | ... CD11: =CC11 -> 0 | CF11: =CD11 -> 0 | CG11: =CF11 -> 0 | CH11: =CG11 -> 0 | CI11: =CH11 -> 0 | CJ11: =CI11 -> 0 | CK11: =CJ11 -> 0 | CL11: =CK11 -> 0 | CM11: =CL11 -> 0 | CN11: =CM11 -> 0 | ... CQ11: =CP11 -> 0 | CS11: =CQ11 -> 0 | CT11: =CS11 -> 0 | CU11: =CT11 -> 0 | CV11: =CU11 -> 0 | CW11: =CV11 -> 0 | CX11: =CW11 -> 0 | CY11: =CX11 -> 0 | CZ11: =CY11 -> 0 | DA11: =CZ11 -> 0 | ... DD11: =DC11 -> 0 | DF11: =DD11 -> 0 | DG11: =DF11 -> 0 | DH11: =DG11 -> 0 | DI11: =DH11 -> 0 | DJ11: =DI11 -> 0 | DK11: =DJ11 -> 0 | DL11: =DK11 -> 0 | DM11: =DL11 -> 0 | DN11: =DM11 -> 0 | ... DQ11: =DP11 -> 0 | DS11: =SUM(F11:Q11)+SUM(S11:AD11)+SUM(AF11:AQ11)+SUM(AS11:BD11)+SUM(BF11:BQ11)+SUM(BS11:CD11)+SUM(CF11:CQ11)+SUM(CS11:DD11)+SUM(DF11:DQ11) -> 0
C12: ='Role Selection'!F9 -> /// | D12: ='Role Selection'!HO9 -> 0 | E12: ='Role Selection'!H9 -> 0 | G12: =F12 -> 0 | H12: =G12 -> 0 | I12: =H12 -> 0 | J12: =I12 -> 0 | K12: =J12 -> 0 | L12: =K12 -> 0 | M12: =L12 -> 0 | N12: =M12 -> 0 | ... Q12: =P12 -> 0 | S12: =+Q12 -> 0 | T12: =S12 -> 0 | U12: =T12 -> 0 | V12: =U12 -> 0 | W12: =V12 -> 0 | X12: =W12 -> 0 | Y12: =X12 -> 0 | Z12: =Y12 -> 0 | AA12: =Z12 -> 0 | ... AD12: =AC12 -> 0 | AF12: =AD12 -> 0 | AG12: =AF12 -> 0 | AH12: =AG12 -> 0 | AI12: =AH12 -> 0 | AJ12: =AI12 -> 0 | AK12: =AJ12 -> 0 | AL12: =AK12 -> 0 | AM12: =AL12 -> 0 | AN12: =AM12 -> 0 | ... AQ12: =AP12 -> 0 | AS12: =AQ12 -> 0 | AT12: =AS12 -> 0 | AU12: =AT12 -> 0 | AV12: =AU12 -> 0 | AW12: =AV12 -> 0 | AX12: =AW12 -> 0 | AY12: =AX12 -> 0 | AZ12: =AY12 -> 0 | BA12: =AZ12 -> 0 | ... BD12: =BC12 -> 0 | BF12: =BD12 -> 0 | BG12: =BF12 -> 0 | BH12: =BG12 -> 0 | BI12: =BH12 -> 0 | BJ12: =BI12 -> 0 | BK12: =BJ12 -> 0 | BL12: =BK12 -> 0 | BM12: =BL12 -> 0 | BN12: =BM12 -> 0 | ... BQ12: =BP12 -> 0 | BS12: =BQ12 -> 0 | BT12: =BS12 -> 0 | BU12: =BT12 -> 0 | BV12: =BU12 -> 0 | BW12: =BV12 -> 0 | BX12: =BW12 -> 0 | BY12: =BX12 -> 0 | BZ12: =BY12 -> 0 | CA12: =BZ12 -> 0 | ... CD12: =CC12 -> 0 | CF12: =CD12 -> 0 | CG12: =CF12 -> 0 | CH12: =CG12 -> 0 | CI12: =CH12 -> 0 | CJ12: =CI12 -> 0 | CK12: =CJ12 -> 0 | CL12: =CK12 -> 0 | CM12: =CL12 -> 0 | CN12: =CM12 -> 0 | ... CQ12: =CP12 -> 0 | CS12: =CQ12 -> 0 | CT12: =CS12 -> 0 | CU12: =CT12 -> 0 | CV12: =CU12 -> 0 | CW12: =CV12 -> 0 | CX12: =CW12 -> 0 | CY12: =CX12 -> 0 | CZ12: =CY12 -> 0 | DA12: =CZ12 -> 0 | ... DD12: =DC12 -> 0 | DF12: =DD12 -> 0 | DG12: =DF12 -> 0 | DH12: =DG12 -> 0 | DI12: =DH12 -> 0 | DJ12: =DI12 -> 0 | DK12: =DJ12 -> 0 | DL12: =DK12 -> 0 | DM12: =DL12 -> 0 | DN12: =DM12 -> 0 | ... DQ12: =DP12 -> 0 | DS12: =SUM(F12:Q12)+SUM(S12:AD12)+SUM(AF12:AQ12)+SUM(AS12:BD12)+SUM(BF12:BQ12)+SUM(BS12:CD12)+SUM(CF12:CQ12)+SUM(CS12:DD12)+SUM(DF12:DQ12) -> 0
A13: 1 | B13: 3 | C13: ='Role Selection'!F10 -> /// | D13: ='Role Selection'!HO10 -> 0 | E13: ='Role Selection'!H10 -> 0 | G13: =F13 -> 0 | H13: =G13 -> 0 | I13: =H13 -> 0 | J13: =I13 -> 0 | K13: =J13 -> 0 | L13: =K13 -> 0 | M13: =L13 -> 0 | N13: =M13 -> 0 | ... Q13: =P13 -> 0 | S13: =+Q13 -> 0 | T13: =S13 -> 0 | U13: =T13 -> 0 | V13: =U13 -> 0 | W13: =V13 -> 0 | X13: =W13 -> 0 | Y13: =X13 -> 0 | Z13: =Y13 -> 0 | AA13: =Z13 -> 0 | ... AD13: =AC13 -> 0 | AF13: =AD13 -> 0 | AG13: =AF13 -> 0 | AH13: =AG13 -> 0 | AI13: =AH13 -> 0 | AJ13: =AI13 -> 0 | AK13: =AJ13 -> 0 | AL13: =AK13 -> 0 | AM13: =AL13 -> 0 | AN13: =AM13 -> 0 | ... AQ13: =AP13 -> 0 | AS13: =AQ13 -> 0 | AT13: =AS13 -> 0 | AU13: =AT13 -> 0 | AV13: =AU13 -> 0 | AW13: =AV13 -> 0 | AX13: =AW13 -> 0 | AY13: =AX13 -> 0 | AZ13: =AY13 -> 0 | BA13: =AZ13 -> 0 | ... BD13: =BC13 -> 0 | BF13: =BD13 -> 0 | BG13: =BF13 -> 0 | BH13: =BG13 -> 0 | BI13: =BH13 -> 0 | BJ13: =BI13 -> 0 | BK13: =BJ13 -> 0 | BL13: =BK13 -> 0 | BM13: =BL13 -> 0 | BN13: =BM13 -> 0 | ... BQ13: =BP13 -> 0 | BS13: =BQ13 -> 0 | BT13: =BS13 -> 0 | BU13: =BT13 -> 0 | BV13: =BU13 -> 0 | BW13: =BV13 -> 0 | BX13: =BW13 -> 0 | BY13: =BX13 -> 0 | BZ13: =BY13 -> 0 | CA13: =BZ13 -> 0 | ... CD13: =CC13 -> 0 | CF13: =CD13 -> 0 | CG13: =CF13 -> 0 | CH13: =CG13 -> 0 | CI13: =CH13 -> 0 | CJ13: =CI13 -> 0 | CK13: =CJ13 -> 0 | CL13: =CK13 -> 0 | CM13: =CL13 -> 0 | CN13: =CM13 -> 0 | ... CQ13: =CP13 -> 0 | CS13: =CQ13 -> 0 | CT13: =CS13 -> 0 | CU13: =CT13 -> 0 | CV13: =CU13 -> 0 | CW13: =CV13 -> 0 | CX13: =CW13 -> 0 | CY13: =CX13 -> 0 | CZ13: =CY13 -> 0 | DA13: =CZ13 -> 0 | ... DD13: =DC13 -> 0 | DF13: =DD13 -> 0 | DG13: =DF13 -> 0 | DH13: =DG13 -> 0 | DI13: =DH13 -> 0 | DJ13: =DI13 -> 0 | DK13: =DJ13 -> 0 | DL13: =DK13 -> 0 | DM13: =DL13 -> 0 | DN13: =DM13 -> 0 | ... DQ13: =DP13 -> 0 | DS13: =SUM(F13:Q13)+SUM(S13:AD13)+SUM(AF13:AQ13)+SUM(AS13:BD13)+SUM(BF13:BQ13)+SUM(BS13:CD13)+SUM(CF13:CQ13)+SUM(CS13:DD13)+SUM(DF13:DQ13) -> 0
C14: ='Role Selection'!F11 -> /// | D14: ='Role Selection'!HO11 -> 0 | E14: ='Role Selection'!H11 -> 0 | G14: =F14 -> 0 | H14: =G14 -> 0 | I14: =H14 -> 0 | J14: =I14 -> 0 | K14: =J14 -> 0 | L14: =K14 -> 0 | M14: =L14 -> 0 | N14: =M14 -> 0 | ... Q14: =P14 -> 0 | S14: =+Q14 -> 0 | T14: =S14 -> 0 | U14: =T14 -> 0 | V14: =U14 -> 0 | W14: =V14 -> 0 | X14: =W14 -> 0 | Y14: =X14 -> 0 | Z14: =Y14 -> 0 | AA14: =Z14 -> 0 | ... AD14: =AC14 -> 0 | AF14: =AD14 -> 0 | AG14: =AF14 -> 0 | AH14: =AG14 -> 0 | AI14: =AH14 -> 0 | AJ14: =AI14 -> 0 | AK14: =AJ14 -> 0 | AL14: =AK14 -> 0 | AM14: =AL14 -> 0 | AN14: =AM14 -> 0 | ... AQ14: =AP14 -> 0 | AS14: =AQ14 -> 0 | AT14: =AS14 -> 0 | AU14: =AT14 -> 0 | AV14: =AU14 -> 0 | AW14: =AV14 -> 0 | AX14: =AW14 -> 0 | AY14: =AX14 -> 0 | AZ14: =AY14 -> 0 | BA14: =AZ14 -> 0 | ... BD14: =BC14 -> 0 | BF14: =BD14 -> 0 | BG14: =BF14 -> 0 | BH14: =BG14 -> 0 | BI14: =BH14 -> 0 | BJ14: =BI14 -> 0 | BK14: =BJ14 -> 0 | BL14: =BK14 -> 0 | BM14: =BL14 -> 0 | BN14: =BM14 -> 0 | ... BQ14: =BP14 -> 0 | BS14: =BQ14 -> 0 | BT14: =BS14 -> 0 | BU14: =BT14 -> 0 | BV14: =BU14 -> 0 | BW14: =BV14 -> 0 | BX14: =BW14 -> 0 | BY14: =BX14 -> 0 | BZ14: =BY14 -> 0 | CA14: =BZ14 -> 0 | ... CD14: =CC14 -> 0 | CF14: =CD14 -> 0 | CG14: =CF14 -> 0 | CH14: =CG14 -> 0 | CI14: =CH14 -> 0 | CJ14: =CI14 -> 0 | CK14: =CJ14 -> 0 | CL14: =CK14 -> 0 | CM14: =CL14 -> 0 | CN14: =CM14 -> 0 | ... CQ14: =CP14 -> 0 | CS14: =CQ14 -> 0 | CT14: =CS14 -> 0 | CU14: =CT14 -> 0 | CV14: =CU14 -> 0 | CW14: =CV14 -> 0 | CX14: =CW14 -> 0 | CY14: =CX14 -> 0 | CZ14: =CY14 -> 0 | DA14: =CZ14 -> 0 | ... DD14: =DC14 -> 0 | DF14: =DD14 -> 0 | DG14: =DF14 -> 0 | DH14: =DG14 -> 0 | DI14: =DH14 -> 0 | DJ14: =DI14 -> 0 | DK14: =DJ14 -> 0 | DL14: =DK14 -> 0 | DM14: =DL14 -> 0 | DN14: =DM14 -> 0 | ... DQ14: =DP14 -> 0 | DS14: =SUM(F14:Q14)+SUM(S14:AD14)+SUM(AF14:AQ14)+SUM(AS14:BD14)+SUM(BF14:BQ14)+SUM(BS14:CD14)+SUM(CF14:CQ14)+SUM(CS14:DD14)+SUM(DF14:DQ14) -> 0
A15: 1 | B15: 4 | C15: ='Role Selection'!F12 -> /// | D15: ='Role Selection'!HO12 -> 0 | E15: ='Role Selection'!H12 -> 0 | G15: =F15 -> 0 | H15: =G15 -> 0 | I15: =H15 -> 0 | J15: =I15 -> 0 | K15: =J15 -> 0 | L15: =K15 -> 0 | M15: =L15 -> 0 | N15: =M15 -> 0 | ... Q15: =P15 -> 0 | S15: =+Q15 -> 0 | T15: =S15 -> 0 | U15: =T15 -> 0 | V15: =U15 -> 0 | W15: =V15 -> 0 | X15: =W15 -> 0 | Y15: =X15 -> 0 | Z15: =Y15 -> 0 | AA15: =Z15 -> 0 | ... AD15: =AC15 -> 0 | AF15: =AD15 -> 0 | AG15: =AF15 -> 0 | AH15: =AG15 -> 0 | AI15: =AH15 -> 0 | AJ15: =AI15 -> 0 | AK15: =AJ15 -> 0 | AL15: =AK15 -> 0 | AM15: =AL15 -> 0 | AN15: =AM15 -> 0 | ... AQ15: =AP15 -> 0 | AS15: =AQ15 -> 0 | AT15: =AS15 -> 0 | AU15: =AT15 -> 0 | AV15: =AU15 -> 0 | AW15: =AV15 -> 0 | AX15: =AW15 -> 0 | AY15: =AX15 -> 0 | AZ15: =AY15 -> 0 | BA15: =AZ15 -> 0 | ... BD15: =BC15 -> 0 | BF15: =BD15 -> 0 | BG15: =BF15 -> 0 | BH15: =BG15 -> 0 | BI15: =BH15 -> 0 | BJ15: =BI15 -> 0 | BK15: =BJ15 -> 0 | BL15: =BK15 -> 0 | BM15: =BL15 -> 0 | BN15: =BM15 -> 0 | ... BQ15: =BP15 -> 0 | BS15: =BQ15 -> 0 | BT15: =BS15 -> 0 | BU15: =BT15 -> 0 | BV15: =BU15 -> 0 | BW15: =BV15 -> 0 | BX15: =BW15 -> 0 | BY15: =BX15 -> 0 | BZ15: =BY15 -> 0 | CA15: =BZ15 -> 0 | ... CD15: =CC15 -> 0 | CF15: =CD15 -> 0 | CG15: =CF15 -> 0 | CH15: =CG15 -> 0 | CI15: =CH15 -> 0 | CJ15: =CI15 -> 0 | CK15: =CJ15 -> 0 | CL15: =CK15 -> 0 | CM15: =CL15 -> 0 | CN15: =CM15 -> 0 | ... CQ15: =CP15 -> 0 | CS15: =CQ15 -> 0 | CT15: =CS15 -> 0 | CU15: =CT15 -> 0 | CV15: =CU15 -> 0 | CW15: =CV15 -> 0 | CX15: =CW15 -> 0 | CY15: =CX15 -> 0 | CZ15: =CY15 -> 0 | DA15: =CZ15 -> 0 | ... DD15: =DC15 -> 0 | DF15: =DD15 -> 0 | DG15: =DF15 -> 0 | DH15: =DG15 -> 0 | DI15: =DH15 -> 0 | DJ15: =DI15 -> 0 | DK15: =DJ15 -> 0 | DL15: =DK15 -> 0 | DM15: =DL15 -> 0 | DN15: =DM15 -> 0 | ... DQ15: =DP15 -> 0 | DS15: =SUM(F15:Q15)+SUM(S15:AD15)+SUM(AF15:AQ15)+SUM(AS15:BD15)+SUM(BF15:BQ15)+SUM(BS15:CD15)+SUM(CF15:CQ15)+SUM(CS15:DD15)+SUM(DF15:DQ15) -> 0
C16: ='Role Selection'!F13 -> /// | D16: ='Role Selection'!HO13 -> 0 | E16: ='Role Selection'!H13 -> 0 | G16: =F16 -> 0 | H16: =G16 -> 0 | I16: =H16 -> 0 | J16: =I16 -> 0 | K16: =J16 -> 0 | L16: =K16 -> 0 | M16: =L16 -> 0 | N16: =M16 -> 0 | ... Q16: =P16 -> 0 | S16: =+Q16 -> 0 | T16: =S16 -> 0 | U16: =T16 -> 0 | V16: =U16 -> 0 | W16: =V16 -> 0 | X16: =W16 -> 0 | Y16: =X16 -> 0 | Z16: =Y16 -> 0 | AA16: =Z16 -> 0 | ... AD16: =AC16 -> 0 | AF16: =AD16 -> 0 | AG16: =AF16 -> 0 | AH16: =AG16 -> 0 | AI16: =AH16 -> 0 | AJ16: =AI16 -> 0 | AK16: =AJ16 -> 0 | AL16: =AK16 -> 0 | AM16: =AL16 -> 0 | AN16: =AM16 -> 0 | ... AQ16: =AP16 -> 0 | AS16: =AQ16 -> 0 | AT16: =AS16 -> 0 | AU16: =AT16 -> 0 | AV16: =AU16 -> 0 | AW16: =AV16 -> 0 | AX16: =AW16 -> 0 | AY16: =AX16 -> 0 | AZ16: =AY16 -> 0 | BA16: =AZ16 -> 0 | ... BD16: =BC16 -> 0 | BF16: =BD16 -> 0 | BG16: =BF16 -> 0 | BH16: =BG16 -> 0 | BI16: =BH16 -> 0 | BJ16: =BI16 -> 0 | BK16: =BJ16 -> 0 | BL16: =BK16 -> 0 | BM16: =BL16 -> 0 | BN16: =BM16 -> 0 | ... BQ16: =BP16 -> 0 | BS16: =BQ16 -> 0 | BT16: =BS16 -> 0 | BU16: =BT16 -> 0 | BV16: =BU16 -> 0 | BW16: =BV16 -> 0 | BX16: =BW16 -> 0 | BY16: =BX16 -> 0 | BZ16: =BY16 -> 0 | CA16: =BZ16 -> 0 | ... CD16: =CC16 -> 0 | CF16: =CD16 -> 0 | CG16: =CF16 -> 0 | CH16: =CG16 -> 0 | CI16: =CH16 -> 0 | CJ16: =CI16 -> 0 | CK16: =CJ16 -> 0 | CL16: =CK16 -> 0 | CM16: =CL16 -> 0 | CN16: =CM16 -> 0 | ... CQ16: =CP16 -> 0 | CS16: =CQ16 -> 0 | CT16: =CS16 -> 0 | CU16: =CT16 -> 0 | CV16: =CU16 -> 0 | CW16: =CV16 -> 0 | CX16: =CW16 -> 0 | CY16: =CX16 -> 0 | CZ16: =CY16 -> 0 | DA16: =CZ16 -> 0 | ... DD16: =DC16 -> 0 | DF16: =DD16 -> 0 | DG16: =DF16 -> 0 | DH16: =DG16 -> 0 | DI16: =DH16 -> 0 | DJ16: =DI16 -> 0 | DK16: =DJ16 -> 0 | DL16: =DK16 -> 0 | DM16: =DL16 -> 0 | DN16: =DM16 -> 0 | ... DQ16: =DP16 -> 0 | DS16: =SUM(F16:Q16)+SUM(S16:AD16)+SUM(AF16:AQ16)+SUM(AS16:BD16)+SUM(BF16:BQ16)+SUM(BS16:CD16)+SUM(CF16:CQ16)+SUM(CS16:DD16)+SUM(DF16:DQ16) -> 0
